one}
‚úÖ User found: admin (email: admin@probeops.com)
INFO:     127.0.0.1:37540 - "GET /subscriptions HTTP/1.1" 500 Internal Server Error
ERROR:    Exception in ASGI application
Traceback (most recent call last):
  File "/home/runner/workspace/.pythonlibs/lib/python3.11/site-packages/uvicorn/protocols/http/h11_impl.py", line 403, in run_asgi
    result = await app(  # type: ignore[func-returns-value]
             ^^^^^^^^^^^^^^^^^^^^^^^^^^^^^^^^^^^^^^^^^^^^^^
  File "/home/runner/workspace/.pythonlibs/lib/python3.11/site-packages/uvicorn/middleware/proxy_headers.py", line 60, in __call__
    return await self.app(scope, receive, send)
           ^^^^^^^^^^^^^^^^^^^^^^^^^^^^^^^^^^^^
  File "/home/runner/workspace/.pythonlibs/lib/python3.11/site-packages/fastapi/applications.py", line 1054, in __call__
    await super().__call__(scope, receive, send)
  File "/home/runner/workspace/.pythonlibs/lib/python3.11/site-packages/starlette/applications.py", line 112, in __call__
    await self.middleware_stack(scope, receive, send)
  File "/home/runner/workspace/.pythonlibs/lib/python3.11/site-packages/starlette/middleware/errors.py", line 187, in __call__
    raise exc
  File "/home/runner/workspace/.pythonlibs/lib/python3.11/site-packages/starlette/middleware/errors.py", line 165, in __call__
    await self.app(scope, receive, _send)
  File "/home/runner/workspace/.pythonlibs/lib/python3.11/site-packages/starlette/middleware/cors.py", line 85, in __call__
    await self.app(scope, receive, send)
  File "/home/runner/workspace/.pythonlibs/lib/python3.11/site-packages/starlette/middleware/exceptions.py", line 62, in __call__
    await wrap_app_handling_exceptions(self.app, conn)(scope, receive, send)
  File "/home/runner/workspace/.pythonlibs/lib/python3.11/site-packages/starlette/_exception_handler.py", line 53, in wrapped_app
    raise exc
  File "/home/runner/workspace/.pythonlibs/lib/python3.11/site-packages/starlette/_exception_handler.py", line 42, in wrapped_app
    await app(scope, receive, sender)
  File "/home/runner/workspace/.pythonlibs/lib/python3.11/site-packages/starlette/routing.py", line 714, in __call__
    await self.middleware_stack(scope, receive, send)
  File "/home/runner/workspace/.pythonlibs/lib/python3.11/site-packages/starlette/routing.py", line 734, in app
    await route.handle(scope, receive, send)
  File "/home/runner/workspace/.pythonlibs/lib/python3.11/site-packages/starlette/routing.py", line 288, in handle
    await self.app(scope, receive, send)
  File "/home/runner/workspace/.pythonlibs/lib/python3.11/site-packages/starlette/routing.py", line 76, in app
    await wrap_app_handling_exceptions(app, request)(scope, receive, send)
  File "/home/runner/workspace/.pythonlibs/lib/python3.11/site-packages/starlette/_exception_handler.py", line 53, in wrapped_app
    raise exc
  File "/home/runner/workspace/.pythonlibs/lib/python3.11/site-packages/starlette/_exception_handler.py", line 42, in wrapped_app
    await app(scope, receive, sender)
  File "/home/runner/workspace/.pythonlibs/lib/python3.11/site-packages/starlette/routing.py", line 73, in app
    response = await f(request)
               ^^^^^^^^^^^^^^^^
  File "/home/runner/workspace/.pythonlibs/lib/python3.11/site-packages/fastapi/routing.py", line 327, in app
    content = await serialize_response(
              ^^^^^^^^^^^^^^^^^^^^^^^^^
  File "/home/runner/workspace/.pythonlibs/lib/python3.11/site-packages/fastapi/routing.py", line 176, in serialize_response
    raise ResponseValidationError(
fastapi.exceptions.ResponseValidationError: 4 validation errors:
  {'type': 'dict_type', 'loc': ('response', 0, 'tier'), 'msg': 'Input should be a valid dictionary', 'input': <app.models.SubscriptionTier object at 0x7f14d2d34310>}
  {'type': 'dict_type', 'loc': ('response', 1, 'tier'), 'msg': 'Input should be a valid dictionary', 'input': <app.models.SubscriptionTier object at 0x7f14d2d34310>}
  {'type': 'dict_type', 'loc': ('response', 2, 'tier'), 'msg': 'Input should be a valid dictionary', 'input': <app.models.SubscriptionTier object at 0x7f14d2d34d90>}
  {'type': 'dict_type', 'loc': ('response', 3, 'tier'), 'msg': 'Input should be a valid dictionary', 'input': <app.models.SubscriptionTier object at 0x7f14d2d34310>}

INFO:     127.0.0.1:37566 - "GET /nodes?skip=0&limit=10&active_only=false HTTP/1.1" 404 Not Found
üîç Decoded JWT payload: {'sub': 'admin@probeops.com', 'exp': 1747298867}
2025-05-15 08:18:01,265 - app.auth - DEBUG - Decoded JWT payload: {'sub': 'admin@probeops.com', 'exp': 1747298867}
üìß Found email in token: admin@probeops.com
‚úÖ TokenPayload validated: {'sub': 'admin@probeops.com', 'exp': None}
2025-05-15 08:18:01,265 - app.auth - DEBUG - TokenPayload validated: {'sub': 'admin@probeops.com', 'exp': None}
‚úÖ User found: admin (email: admin@probeops.com)
INFO:     127.0.0.1:37552 - "GET /nodes/registration-token?include_expired=false&include_used=false HTTP/1.1" 200 OK
