 Container probenetworktools-backend-1  Started
 Container probenetworktools-probe-1  Starting
 Container probenetworktools-nginx-1  Starting
 Container probenetworktools-probe-1  Started
 Container probenetworktools-nginx-1  Started
âœ… Docker containers built and started successfully
ðŸ”„ Waiting for backend service to be ready...
ðŸ”„ Applying database migrations to AWS RDS
time="2025-05-13T09:42:13Z" level=warning msg="The \"PROBE_API_KEY\" variable is not set. Defaulting to a blank string."
Traceback (most recent call last):
  File "/usr/local/lib/python3.11/site-packages/pydantic_settings/sources/base.py", line 482, in __call__
    field_value = self.prepare_field_value(field_name, field, field_value, value_is_complex)
                  ^^^^^^^^^^^^^^^^^^^^^^^^^^^^^^^^^^^^^^^^^^^^^^^^^^^^^^^^^^^^^^^^^^^^^^^^^^
  File "/usr/local/lib/python3.11/site-packages/pydantic_settings/sources/providers/env.py", line 120, in prepare_field_value
    raise e
  File "/usr/local/lib/python3.11/site-packages/pydantic_settings/sources/providers/env.py", line 117, in prepare_field_value
    value = self.decode_complex_value(field_name, field, value)
            ^^^^^^^^^^^^^^^^^^^^^^^^^^^^^^^^^^^^^^^^^^^^^^^^^^^
  File "/usr/local/lib/python3.11/site-packages/pydantic_settings/sources/base.py", line 186, in decode_complex_value
    return json.loads(value)
           ^^^^^^^^^^^^^^^^^
  File "/usr/local/lib/python3.11/json/__init__.py", line 346, in loads
    return _default_decoder.decode(s)
           ^^^^^^^^^^^^^^^^^^^^^^^^^^
  File "/usr/local/lib/python3.11/json/decoder.py", line 337, in decode
    obj, end = self.raw_decode(s, idx=_w(s, 0).end())
               ^^^^^^^^^^^^^^^^^^^^^^^^^^^^^^^^^^^^^^
  File "/usr/local/lib/python3.11/json/decoder.py", line 355, in raw_decode
    raise JSONDecodeError("Expecting value", s, err.value) from None
json.decoder.JSONDecodeError: Expecting value: line 1 column 1 (char 0)

The above exception was the direct cause of the following exception:

Traceback (most recent call last):
  File "/usr/local/bin/alembic", line 8, in <module>
    sys.exit(main())
             ^^^^^^
  File "/usr/local/lib/python3.11/site-packages/alembic/config.py", line 636, in main
    CommandLine(prog=prog).main(argv=argv)
  File "/usr/local/lib/python3.11/site-packages/alembic/config.py", line 626, in main
    self.run_cmd(cfg, options)
  File "/usr/local/lib/python3.11/site-packages/alembic/config.py", line 603, in run_cmd
    fn(
  File "/usr/local/lib/python3.11/site-packages/alembic/command.py", line 408, in upgrade
    script.run_env()
  File "/usr/local/lib/python3.11/site-packages/alembic/script/base.py", line 586, in run_env
    util.load_python_file(self.dir, "env.py")
  File "/usr/local/lib/python3.11/site-packages/alembic/util/pyfiles.py", line 95, in load_python_file
    module = load_module_py(module_id, path)
             ^^^^^^^^^^^^^^^^^^^^^^^^^^^^^^^
  File "/usr/local/lib/python3.11/site-packages/alembic/util/pyfiles.py", line 113, in load_module_py
    spec.loader.exec_module(module)  # type: ignore
    ^^^^^^^^^^^^^^^^^^^^^^^^^^^^^^^
  File "<frozen importlib._bootstrap_external>", line 940, in exec_module
  File "<frozen importlib._bootstrap>", line 241, in _call_with_frames_removed
  File "/app/alembic/env.py", line 14, in <module>
    from app.models import Base
  File "/app/app/models.py", line 5, in <module>
    from .database import Base
  File "/app/app/database.py", line 5, in <module>
    from .config import settings
  File "/app/app/config.py", line 38, in <module>
    settings = Settings()
               ^^^^^^^^^^
  File "/usr/local/lib/python3.11/site-packages/pydantic_settings/main.py", line 177, in __init__
    **__pydantic_self__._settings_build_values(
      ^^^^^^^^^^^^^^^^^^^^^^^^^^^^^^^^^^^^^^^^^
  File "/usr/local/lib/python3.11/site-packages/pydantic_settings/main.py", line 408, in _settings_build_values
    source_state = source()
                   ^^^^^^^^
  File "/usr/local/lib/python3.11/site-packages/pydantic_settings/sources/base.py", line 484, in __call__
    raise SettingsError(
pydantic_settings.exceptions.SettingsError: error parsing value for field "CORS_ORIGINS" from source "EnvSettingsSource"
